Workbook

Sheet Read me
A1: Gainsay — revised business plan | B1: Main Scenario
A2: Forecast | B2: October 2026–December 2027
A3: Input policy | B3: All original input values retained; new assumptions are explicitly labeled.
A4: Monthly cash basis | B4: Opening cash minus launch cost, then monthly result; data fee reserved monthly.
A5: Annual-upfront cash basis | B5: Original Ending cash row pays data fee upfront each October. Do not treat monthly reserves as actual installment terms.
A6: Founder draw | B6: Included in cash costs; not accounting salary or profit.
A7: Raised API access cost | B7: Unquoted. $0 is an unpriced placeholder, not free access. Incremental recurring cost starts at first quota crossing; do not double-count an upgrade bundled into the data agreement.
A8: Conservative / measured API | B8: 2 / 0.8 calls per citation. Mata ECF 21: about 13 calls / 16 citations = 0.8125; use 0.8 as the requested rounded case, not a universal benchmark.
A9: Quota calculation | B9: Monthly check calls / 30.4 plus daily docket polls. Default 125/day; hour/minute and burst limits can bind earlier. Commercial permission is separate from throughput.
A10: Cash correction | B10: First negative June 2027 (-$29.89); lowest July (-$53.20); first positive monthly result August 2027.
A11: Loss before first positive month | B11: $4,553.20; opening cash after launch is $4,500.
A12: Cash buffer | B12: Three months of $1,010.60 fixed budget = $3,031.80. Minimum monthly-reserved opening cash $8,085; rounded recommendation $8,500. Existing opening input stays $5,000.
... A23: Quota documentation | B23: https://wiki.free.law/c/courtlistener/help/api/rest/v4/api-usage

Sheet Gainsay drivers · Gainsay fixed
A1: Gainsay drivers · Gainsay fixed assumptions
A2: Financial model (3 pages) · Main Scenario
A4: Variable / dimension | B4: Value
A5: Claude cost per citation | B5: 0.026
A6: Docket monthly price | B6: 29
A7: Brief price | B7: 9
A8: New filings per docket | B8: 2
A9: Citations per paid filing | B9: 35
A10: Citations per free check | B10: 30
A11: Global free checks per month | B11: 20
A12: API calls per citation | B12: 2
A13: Daily default API quota | B13: 125
A14: Poll calls per docket per day | B14: 1
A15: Hosting per month | B15: 15
A16: Tools per month | B16: 30
... A35: Observed Mata citations | B35: 16

Sheet Gainsay drivers · Gainsay deman
A1: Gainsay drivers · Gainsay demand assumptions
A2: Financial model (3 pages) · Main Scenario
A4: Variable / dimension | B4: 2026-10 | C4: 2026-11 | D4: 2026-12 | E4: 2027-01 | F4: 2027-02 | G4: 2027-03 | H4: 2027-04 | I4: 2027-05 | J4: 2027-06 | K4: 2027-07 | L4: 2027-08 | M4: 2027-09 | N4: 2027-10 | O4: 2027-11 | P4: 2027-12
A5: New dockets per month | B5: 3 | C5: ='Gainsay drivers · Gainsay deman'!B5*(1+'Gainsay drivers · Gainsay deman'!C6) -> 3.15 | D5: ='Gainsay drivers · Gainsay deman'!C5*(1+'Gainsay drivers · Gainsay deman'!D6) -> 3.3075 | E5: ='Gainsay drivers · Gainsay deman'!D5*(1+'Gainsay drivers · Gainsay deman'!E6) -> 3.472875 | F5: ='Gainsay drivers · Gainsay deman'!E5*(1+'Gainsay drivers · Gainsay deman'!F6) -> 3.6465187 | G5: ='Gainsay drivers · Gainsay deman'!F5*(1+'Gainsay drivers · Gainsay deman'!G6) -> 3.8288447 | H5: ='Gainsay drivers · Gainsay deman'!G5*(1+'Gainsay drivers · Gainsay deman'!H6) -> 4.0202869 | I5: ='Gainsay drivers · Gainsay deman'!H5*(1+'Gainsay drivers · Gainsay deman'!I6) -> 4.2213013 | J5: ='Gainsay drivers · Gainsay deman'!I5*(1+'Gainsay drivers · Gainsay deman'!J6) -> 4.4323663 | ... P5: ='Gainsay drivers · Gainsay deman'!O5*(1+'Gainsay drivers · Gainsay deman'!P6) -> 5.9397948
A6: Monthly acquisition growth | B6: 0.05 | C6: =IF('Gainsay drivers · Gainsay deman'!B6="","",'Gainsay drivers · Gainsay deman'!B6) -> 0.05 | D6: =IF('Gainsay drivers · Gainsay deman'!C6="","",'Gainsay drivers · Gainsay deman'!C6) -> 0.05 | E6: =IF('Gainsay drivers · Gainsay deman'!D6="","",'Gainsay drivers · Gainsay deman'!D6) -> 0.05 | F6: =IF('Gainsay drivers · Gainsay deman'!E6="","",'Gainsay drivers · Gainsay deman'!E6) -> 0.05 | G6: =IF('Gainsay drivers · Gainsay deman'!F6="","",'Gainsay drivers · Gainsay deman'!F6) -> 0.05 | H6: =IF('Gainsay drivers · Gainsay deman'!G6="","",'Gainsay drivers · Gainsay deman'!G6) -> 0.05 | I6: =IF('Gainsay drivers · Gainsay deman'!H6="","",'Gainsay drivers · Gainsay deman'!H6) -> 0.05 | J6: =IF('Gainsay drivers · Gainsay deman'!I6="","",'Gainsay drivers · Gainsay deman'!I6) -> 0.05 | ... P6: =IF('Gainsay drivers · Gainsay deman'!O6="","",'Gainsay drivers · Gainsay deman'!O6) -> 0.05
A7: Monthly docket churn | B7: 0.03 | C7: =IF('Gainsay drivers · Gainsay deman'!B7="","",'Gainsay drivers · Gainsay deman'!B7) -> 0.03 | D7: =IF('Gainsay drivers · Gainsay deman'!C7="","",'Gainsay drivers · Gainsay deman'!C7) -> 0.03 | E7: =IF('Gainsay drivers · Gainsay deman'!D7="","",'Gainsay drivers · Gainsay deman'!D7) -> 0.03 | F7: =IF('Gainsay drivers · Gainsay deman'!E7="","",'Gainsay drivers · Gainsay deman'!E7) -> 0.03 | G7: =IF('Gainsay drivers · Gainsay deman'!F7="","",'Gainsay drivers · Gainsay deman'!F7) -> 0.03 | H7: =IF('Gainsay drivers · Gainsay deman'!G7="","",'Gainsay drivers · Gainsay deman'!G7) -> 0.03 | I7: =IF('Gainsay drivers · Gainsay deman'!H7="","",'Gainsay drivers · Gainsay deman'!H7) -> 0.03 | J7: =IF('Gainsay drivers · Gainsay deman'!I7="","",'Gainsay drivers · Gainsay deman'!I7) -> 0.03 | ... P7: =IF('Gainsay drivers · Gainsay deman'!O7="","",'Gainsay drivers · Gainsay deman'!O7) -> 0.03
A8: Brief checks sold | B8: 10 | C8: ='Gainsay drivers · Gainsay deman'!B8*(1+'Gainsay drivers · Gainsay deman'!C9) -> 10.5 | D8: ='Gainsay drivers · Gainsay deman'!C8*(1+'Gainsay drivers · Gainsay deman'!D9) -> 11.025 | E8: ='Gainsay drivers · Gainsay deman'!D8*(1+'Gainsay drivers · Gainsay deman'!E9) -> 11.57625 | F8: ='Gainsay drivers · Gainsay deman'!E8*(1+'Gainsay drivers · Gainsay deman'!F9) -> 12.155062 | G8: ='Gainsay drivers · Gainsay deman'!F8*(1+'Gainsay drivers · Gainsay deman'!G9) -> 12.762816 | H8: ='Gainsay drivers · Gainsay deman'!G8*(1+'Gainsay drivers · Gainsay deman'!H9) -> 13.400956 | I8: ='Gainsay drivers · Gainsay deman'!H8*(1+'Gainsay drivers · Gainsay deman'!I9) -> 14.071004 | J8: ='Gainsay drivers · Gainsay deman'!I8*(1+'Gainsay drivers · Gainsay deman'!J9) -> 14.774554 | ... P8: ='Gainsay drivers · Gainsay deman'!O8*(1+'Gainsay drivers · Gainsay deman'!P9) -> 19.799316
A9: Monthly brief demand growth | B9: 0.05 | C9: =IF('Gainsay drivers · Gainsay deman'!B9="","",'Gainsay drivers · Gainsay deman'!B9) -> 0.05 | D9: =IF('Gainsay drivers · Gainsay deman'!C9="","",'Gainsay drivers · Gainsay deman'!C9) -> 0.05 | E9: =IF('Gainsay drivers · Gainsay deman'!D9="","",'Gainsay drivers · Gainsay deman'!D9) -> 0.05 | F9: =IF('Gainsay drivers · Gainsay deman'!E9="","",'Gainsay drivers · Gainsay deman'!E9) -> 0.05 | G9: =IF('Gainsay drivers · Gainsay deman'!F9="","",'Gainsay drivers · Gainsay deman'!F9) -> 0.05 | H9: =IF('Gainsay drivers · Gainsay deman'!G9="","",'Gainsay drivers · Gainsay deman'!G9) -> 0.05 | I9: =IF('Gainsay drivers · Gainsay deman'!H9="","",'Gainsay drivers · Gainsay deman'!H9) -> 0.05 | J9: =IF('Gainsay drivers · Gainsay deman'!I9="","",'Gainsay drivers · Gainsay deman'!I9) -> 0.05 | ... P9: =IF('Gainsay drivers · Gainsay deman'!O9="","",'Gainsay drivers · Gainsay deman'!O9) -> 0.05

Sheet Gainsay drivers · Gainsay prici
A1: Gainsay drivers · Gainsay pricing economics
A2: Financial model (3 pages) · Main Scenario
A4: Variable / dimension | B4: Value
A5: AI cost per average filing | B5: ='Gainsay drivers · Gainsay fixed'!B5*'Gainsay drivers · Gainsay fixed'!B9 -> 0.91
A6: AI cost at 15 citations | B6: ='Gainsay drivers · Gainsay fixed'!B5*15 -> 0.39
A7: AI cost at 50 citations | B7: ='Gainsay drivers · Gainsay fixed'!B5*50 -> 1.3
A8: Docket contribution per month | B8: ='Gainsay drivers · Gainsay fixed'!B6*(1-'Gainsay drivers · Gainsay fixed'!B23)-'Gainsay drivers · Gainsay fixed'!B24-'Gainsay drivers · Gainsay fixed'!B8*'Gainsay drivers · Gainsay prici'!B5 -> 26.039
A9: Brief contribution | B9: ='Gainsay drivers · Gainsay fixed'!B7*(1-'Gainsay drivers · Gainsay fixed'!B23)-'Gainsay drivers · Gainsay fixed'!B24-'Gainsay drivers · Gainsay prici'!B5 -> 7.529
A10: Fixed monthly cash budget | B10: ='Gainsay drivers · Gainsay fixed'!B15+'Gainsay drivers · Gainsay fixed'!B16+'Gainsay drivers · Gainsay fixed'!B17+'Gainsay drivers · Gainsay fixed'!B18+'Gainsay drivers · Gainsay fixed'!B20/12+'Gainsay drivers · Gainsay fixed'!B19+'Gainsay drivers · Gainsay fixed'!B11*'Gainsay drivers · Gainsay fixed'!B10*'Gainsay drivers · Gainsay fixed'!B5 -> 1010.6
A11: Dockets needed for fixed cash budget | B11: =CEILING('Gainsay drivers · Gainsay prici'!B10/'Gainsay drivers · Gainsay prici'!B8,1) -> 39
A12: Observed Mata calls per citation | B12: ='Gainsay drivers · Gainsay fixed'!B34/'Gainsay drivers · Gainsay fixed'!B35 -> 0.8125
A13: Cash after launch | B13: ='Gainsay drivers · Gainsay fixed'!B21-'Gainsay drivers · Gainsay fixed'!B22 -> 4500
A14: Lowest monthly-reserved cash | B14: =MIN('Gainsay economics · Gainsay ope'!B12,'Gainsay economics · Gainsay ope'!C12,'Gainsay economics · Gainsay ope'!D12,'Gainsay economics · Gainsay ope'!E12,'Gainsay economics · Gainsay ope'!F12,'Gainsay economics · Gainsay ope'!G12,'Gainsay economics · Gainsay ope'!H12,'Gainsay economics · Gainsay ope'!I12,'Gainsay economics · Gainsay ope'!J12,'Gainsay economics · Gainsay ope'!K12,'Gainsay economics · Gainsay ope'!L12,'Gainsay economics · Gainsay ope'!M12,'Gainsay economics · Gainsay ope'!N12,'Gainsay economics · Gainsay ope'!O12,'Gainsay economics · Gainsay ope'!P12) -> -53.199018
A15: Losses before first positive month | B15: =-'Model inputs'!B295 -> 4553.199
A16: First positive month | B16: =IF('Model inputs'!B359="","",EDATE(DATE(2026,10,1),IF((IF(AND('Model inputs'!B335="",'Model inputs'!B336="",'Model inputs'!B337="",'Model inputs'!B338="",'Model inputs'!B339="",'Model inputs'!B340="",'Model inputs'!B341="",'Model inputs'!B342="",'Model inputs'!B343="",'Model inputs'!B344="",'Model inputs'!B345="",'Model inputs'!B346="",'Model inputs'!B347="",'Model inputs'!B348="",'Model inputs'!B349="",'Model inputs'!B350="",'Model inputs'!B351="",'Model inputs'!B352="",'Model inputs'!B353="",'Model inputs'!B354="",'Model inputs'!B355="",'Model inputs'!B356="",'Model inputs'!B357="",'Model inputs'!B358=""),"",MIN('Model inputs'!B335,'Model inputs'!B336,'Model inputs'!B337,'Model inputs'!B338,'Model inputs'!B339,'Model inputs'!B340,'Model inputs'!B341,'Model inputs'!B342,'Model inputs'!B343,'Model inputs'!B344,'Model inputs'!B345,'Model inputs'!B346,'Model inputs'!B347,'Model inputs'!B348,'Model inputs'!B349,'Model inputs'!B350,'Model inputs'!B351,'Model inputs'!B352,'Model inputs'!B353,'Model inputs'!B354,'Model inputs'!B355,'Model inputs'!B356,'Model inputs'!B357,'Model inputs'!B358)))="",0,(IF(AND('Model inputs'!B335="",'Model inputs'!B336="",'Model inputs'!B337="",'Model inputs'!B338="",'Model inputs'!B339="",'Model inputs'!B340="",'Model inputs'!B341="",'Model inputs'!B342="",'Model inputs'!B343="",'Model inputs'!B344="",'Model inputs'!B345="",'Model inputs'!B346="",'Model inputs'!B347="",'Model inputs'!B348="",'Model inputs'!B349="",'Model inputs'!B350="",'Model inputs'!B351="",'Model inputs'!B352="",'Model inputs'!B353="",'Model inputs'!B354="",'Model inputs'!B355="",'Model inputs'!B356="",'Model inputs'!B357="",'Model inputs'!B358=""),"",MIN('Model inputs'!B335,'Model inputs'!B336,'Model inputs'!B337,'Model inputs'!B338,'Model inputs'!B339,'Model inputs'!B340,'Model inputs'!B341,'Model inputs'!B342,'Model inputs'!B343,'Model inputs'!B344,'Model inputs'!B345,'Model inputs'!B346,'Model inputs'!B347,'Model inputs'!B348,'Model inputs'!B349,'Model inputs'!B350,'Model inputs'!B351,'Model inputs'!B352,'Model inputs'!B353,'Model inputs'!B354,'Model inputs'!B355,'Model inputs'!B356,'Model inputs'!B357,'Model inputs'!B358))))-1)) -> 46600
A17: First negative cash month monthly reserved | B17: =IF('Model inputs'!B423="","",EDATE(DATE(2026,10,1),IF((IF(AND('Model inputs'!B399="",'Model inputs'!B400="",'Model inputs'!B401="",'Model inputs'!B402="",'Model inputs'!B403="",'Model inputs'!B404="",'Model inputs'!B405="",'Model inputs'!B406="",'Model inputs'!B407="",'Model inputs'!B408="",'Model inputs'!B409="",'Model inputs'!B410="",'Model inputs'!B411="",'Model inputs'!B412="",'Model inputs'!B413="",'Model inputs'!B414="",'Model inputs'!B415="",'Model inputs'!B416="",'Model inputs'!B417="",'Model inputs'!B418="",'Model inputs'!B419="",'Model inputs'!B420="",'Model inputs'!B421="",'Model inputs'!B422=""),"",MIN('Model inputs'!B399,'Model inputs'!B400,'Model inputs'!B401,'Model inputs'!B402,'Model inputs'!B403,'Model inputs'!B404,'Model inputs'!B405,'Model inputs'!B406,'Model inputs'!B407,'Model inputs'!B408,'Model inputs'!B409,'Model inputs'!B410,'Model inputs'!B411,'Model inputs'!B412,'Model inputs'!B413,'Model inputs'!B414,'Model inputs'!B415,'Model inputs'!B416,'Model inputs'!B417,'Model inputs'!B418,'Model inputs'!B419,'Model inputs'!B420,'Model inputs'!B421,'Model inputs'!B422)))="",0,(IF(AND('Model inputs'!B399="",'Model inputs'!B400="",'Model inputs'!B401="",'Model inputs'!B402="",'Model inputs'!B403="",'Model inputs'!B404="",'Model inputs'!B405="",'Model inputs'!B406="",'Model inputs'!B407="",'Model inputs'!B408="",'Model inputs'!B409="",'Model inputs'!B410="",'Model inputs'!B411="",'Model inputs'!B412="",'Model inputs'!B413="",'Model inputs'!B414="",'Model inputs'!B415="",'Model inputs'!B416="",'Model inputs'!B417="",'Model inputs'!B418="",'Model inputs'!B419="",'Model inputs'!B420="",'Model inputs'!B421="",'Model inputs'!B422=""),"",MIN('Model inputs'!B399,'Model inputs'!B400,'Model inputs'!B401,'Model inputs'!B402,'Model inputs'!B403,'Model inputs'!B404,'Model inputs'!B405,'Model inputs'!B406,'Model inputs'!B407,'Model inputs'!B408,'Model inputs'!B409,'Model inputs'!B410,'Model inputs'!B411,'Model inputs'!B412,'Model inputs'!B413,'Model inputs'!B414,'Model inputs'!B415,'Model inputs'!B416,'Model inputs'!B417,'Model inputs'!B418,'Model inputs'!B419,'Model inputs'!B420,'Model inputs'!B421,'Model inputs'!B422))))-1)) -> 46539
A18: Lowest cash month monthly reserved | B18: =IF('Model inputs'!B496="","",EDATE(DATE(2026,10,1),IF((IF(AND('Model inputs'!B472="",'Model inputs'!B473="",'Model inputs'!B474="",'Model inputs'!B475="",'Model inputs'!B476="",'Model inputs'!B477="",'Model inputs'!B478="",'Model inputs'!B479="",'Model inputs'!B480="",'Model inputs'!B481="",'Model inputs'!B482="",'Model inputs'!B483="",'Model inputs'!B484="",'Model inputs'!B485="",'Model inputs'!B486="",'Model inputs'!B487="",'Model inputs'!B488="",'Model inputs'!B489="",'Model inputs'!B490="",'Model inputs'!B491="",'Model inputs'!B492="",'Model inputs'!B493="",'Model inputs'!B494="",'Model inputs'!B495=""),"",MIN('Model inputs'!B472,'Model inputs'!B473,'Model inputs'!B474,'Model inputs'!B475,'Model inputs'!B476,'Model inputs'!B477,'Model inputs'!B478,'Model inputs'!B479,'Model inputs'!B480,'Model inputs'!B481,'Model inputs'!B482,'Model inputs'!B483,'Model inputs'!B484,'Model inputs'!B485,'Model inputs'!B486,'Model inputs'!B487,'Model inputs'!B488,'Model inputs'!B489,'Model inputs'!B490,'Model inputs'!B491,'Model inputs'!B492,'Model inputs'!B493,'Model inputs'!B494,'Model inputs'!B495)))="",0,(IF(AND('Model inputs'!B472="",'Model inputs'!B473="",'Model inputs'!B474="",'Model inputs'!B475="",'Model inputs'!B476="",'Model inputs'!B477="",'Model inputs'!B478="",'Model inputs'!B479="",'Model inputs'!B480="",'Model inputs'!B481="",'Model inputs'!B482="",'Model inputs'!B483="",'Model inputs'!B484="",'Model inputs'!B485="",'Model inputs'!B486="",'Model inputs'!B487="",'Model inputs'!B488="",'Model inputs'!B489="",'Model inputs'!B490="",'Model inputs'!B491="",'Model inputs'!B492="",'Model inputs'!B493="",'Model inputs'!B494="",'Model inputs'!B495=""),"",MIN('Model inputs'!B472,'Model inputs'!B473,'Model inputs'!B474,'Model inputs'!B475,'Model inputs'!B476,'Model inputs'!B477,'Model inputs'!B478,'Model inputs'!B479,'Model inputs'!B480,'Model inputs'!B481,'Model inputs'!B482,'Model inputs'!B483,'Model inputs'!B484,'Model inputs'!B485,'Model inputs'!B486,'Model inputs'!B487,'Model inputs'!B488,'Model inputs'!B489,'Model inputs'!B490,'Model inputs'!B491,'Model inputs'!B492,'Model inputs'!B493,'Model inputs'!B494,'Model inputs'!B495))))-1)) -> 46569
A19: First API quota month conservative | B19: =IF('Model inputs'!B560="","",EDATE(DATE(2026,10,1),IF((IF(AND('Model inputs'!B536="",'Model inputs'!B537="",'Model inputs'!B538="",'Model inputs'!B539="",'Model inputs'!B540="",'Model inputs'!B541="",'Model inputs'!B542="",'Model inputs'!B543="",'Model inputs'!B544="",'Model inputs'!B545="",'Model inputs'!B546="",'Model inputs'!B547="",'Model inputs'!B548="",'Model inputs'!B549="",'Model inputs'!B550="",'Model inputs'!B551="",'Model inputs'!B552="",'Model inputs'!B553="",'Model inputs'!B554="",'Model inputs'!B555="",'Model inputs'!B556="",'Model inputs'!B557="",'Model inputs'!B558="",'Model inputs'!B559=""),"",MIN('Model inputs'!B536,'Model inputs'!B537,'Model inputs'!B538,'Model inputs'!B539,'Model inputs'!B540,'Model inputs'!B541,'Model inputs'!B542,'Model inputs'!B543,'Model inputs'!B544,'Model inputs'!B545,'Model inputs'!B546,'Model inputs'!B547,'Model inputs'!B548,'Model inputs'!B549,'Model inputs'!B550,'Model inputs'!B551,'Model inputs'!B552,'Model inputs'!B553,'Model inputs'!B554,'Model inputs'!B555,'Model inputs'!B556,'Model inputs'!B557,'Model inputs'!B558,'Model inputs'!B559)))="",0,(IF(AND('Model inputs'!B536="",'Model inputs'!B537="",'Model inputs'!B538="",'Model inputs'!B539="",'Model inputs'!B540="",'Model inputs'!B541="",'Model inputs'!B542="",'Model inputs'!B543="",'Model inputs'!B544="",'Model inputs'!B545="",'Model inputs'!B546="",'Model inputs'!B547="",'Model inputs'!B548="",'Model inputs'!B549="",'Model inputs'!B550="",'Model inputs'!B551="",'Model inputs'!B552="",'Model inputs'!B553="",'Model inputs'!B554="",'Model inputs'!B555="",'Model inputs'!B556="",'Model inputs'!B557="",'Model inputs'!B558="",'Model inputs'!B559=""),"",MIN('Model inputs'!B536,'Model inputs'!B537,'Model inputs'!B538,'Model inputs'!B539,'Model inputs'!B540,'Model inputs'!B541,'Model inputs'!B542,'Model inputs'!B543,'Model inputs'!B544,'Model inputs'!B545,'Model inputs'!B546,'Model inputs'!B547,'Model inputs'!B548,'Model inputs'!B549,'Model inputs'!B550,'Model inputs'!B551,'Model inputs'!B552,'Model inputs'!B553,'Model inputs'!B554,'Model inputs'!B555,'Model inputs'!B556,'Model inputs'!B557,'Model inputs'!B558,'Model inputs'!B559))))-1)) -> 46388
A20: First API quota month measured | B20: =IF('Model inputs'!B624="","",EDATE(DATE(2026,10,1),IF((IF(AND('Model inputs'!B600="",'Model inputs'!B601="",'Model inputs'!B602="",'Model inputs'!B603="",'Model inputs'!B604="",'Model inputs'!B605="",'Model inputs'!B606="",'Model inputs'!B607="",'Model inputs'!B608="",'Model inputs'!B609="",'Model inputs'!B610="",'Model inputs'!B611="",'Model inputs'!B612="",'Model inputs'!B613="",'Model inputs'!B614="",'Model inputs'!B615="",'Model inputs'!B616="",'Model inputs'!B617="",'Model inputs'!B618="",'Model inputs'!B619="",'Model inputs'!B620="",'Model inputs'!B621="",'Model inputs'!B622="",'Model inputs'!B623=""),"",MIN('Model inputs'!B600,'Model inputs'!B601,'Model inputs'!B602,'Model inputs'!B603,'Model inputs'!B604,'Model inputs'!B605,'Model inputs'!B606,'Model inputs'!B607,'Model inputs'!B608,'Model inputs'!B609,'Model inputs'!B610,'Model inputs'!B611,'Model inputs'!B612,'Model inputs'!B613,'Model inputs'!B614,'Model inputs'!B615,'Model inputs'!B616,'Model inputs'!B617,'Model inputs'!B618,'Model inputs'!B619,'Model inputs'!B620,'Model inputs'!B621,'Model inputs'!B622,'Model inputs'!B623)))="",0,(IF(AND('Model inputs'!B600="",'Model inputs'!B601="",'Model inputs'!B602="",'Model inputs'!B603="",'Model inputs'!B604="",'Model inputs'!B605="",'Model inputs'!B606="",'Model inputs'!B607="",'Model inputs'!B608="",'Model inputs'!B609="",'Model inputs'!B610="",'Model inputs'!B611="",'Model inputs'!B612="",'Model inputs'!B613="",'Model inputs'!B614="",'Model inputs'!B615="",'Model inputs'!B616="",'Model inputs'!B617="",'Model inputs'!B618="",'Model inputs'!B619="",'Model inputs'!B620="",'Model inputs'!B621="",'Model inputs'!B622="",'Model inputs'!B623=""),"",MIN('Model inputs'!B600,'Model inputs'!B601,'Model inputs'!B602,'Model inputs'!B603,'Model inputs'!B604,'Model inputs'!B605,'Model inputs'!B606,'Model inputs'!B607,'Model inputs'!B608,'Model inputs'!B609,'Model inputs'!B610,'Model inputs'!B611,'Model inputs'!B612,'Model inputs'!B613,'Model inputs'!B614,'Model inputs'!B615,'Model inputs'!B616,'Model inputs'!B617,'Model inputs'!B618,'Model inputs'!B619,'Model inputs'!B620,'Model inputs'!B621,'Model inputs'!B622,'Model inputs'!B623))))-1)) -> 46569
A21: Three month fixed budget buffer | B21: ='Gainsay drivers · Gainsay fixed'!B31*('Gainsay drivers · Gainsay prici'!B10+'Gainsay drivers · Gainsay fixed'!B30) -> 3031.8
A22: Minimum opening cash monthly reserved | B22: ='Gainsay drivers · Gainsay fixed'!B21+'Gainsay drivers · Gainsay prici'!B21-'Gainsay drivers · Gainsay prici'!B14 -> 8084.999
A23: Recommended opening cash monthly reserved | B23: =CEILING('Gainsay drivers · Gainsay prici'!B22,'Gainsay drivers · Gainsay fixed'!B33) -> 8500
A24: Minimum opening cash annual upfront | B24: ='Gainsay drivers · Gainsay fixed'!B21+'Gainsay drivers · Gainsay prici'!B21-MIN('Gainsay economics · Gainsay ope'!B33,'Gainsay economics · Gainsay ope'!C33,'Gainsay economics · Gainsay ope'!D33,'Gainsay economics · Gainsay ope'!E33,'Gainsay economics · Gainsay ope'!F33,'Gainsay economics · Gainsay ope'!G33,'Gainsay economics · Gainsay ope'!H33,'Gainsay economics · Gainsay ope'!I33,'Gainsay economics · Gainsay ope'!J33,'Gainsay economics · Gainsay ope'!K33,'Gainsay economics · Gainsay ope'!L33,'Gainsay economics · Gainsay ope'!M33,'Gainsay economics · Gainsay ope'!N33,'Gainsay economics · Gainsay ope'!O33,'Gainsay economics · Gainsay ope'!P33) -> 10248.406
A25: Recommended opening cash annual upfront | B25: =CEILING('Gainsay drivers · Gainsay prici'!B24,'Gainsay drivers · Gainsay fixed'!B33) -> 10500
A26: API calls at 39 dockets with opening brief volume | B26: =((39*'Gainsay drivers · Gainsay fixed'!B8+'Gainsay drivers · Gainsay deman'!B8)*'Gainsay drivers · Gainsay fixed'!B9+'Gainsay drivers · Gainsay fixed'!B11*'Gainsay drivers · Gainsay fixed'!B10)*'Gainsay drivers · Gainsay fixed'!B12/'Gainsay drivers · Gainsay fixed'!B32+39*'Gainsay drivers · Gainsay fixed'!B14 -> 281.10526
A27: API calls at 39 dockets excluding brief checks | B27: =(39*'Gainsay drivers · Gainsay fixed'!B8*'Gainsay drivers · Gainsay fixed'!B9+'Gainsay drivers · Gainsay fixed'!B11*'Gainsay drivers · Gainsay fixed'!B10)*'Gainsay drivers · Gainsay fixed'!B12/'Gainsay drivers · Gainsay fixed'!B32+39*'Gainsay drivers · Gainsay fixed'!B14 -> 258.07895

Sheet Gainsay drivers · Gainsay data-
A1: Gainsay drivers · Gainsay data-fee tests
A2: Financial model (3 pages) · Main Scenario
A4: Variable / dimension | B4: Test annual data fee | C4: Test fixed monthly cash budget | D4: Test dockets needed for fixed cash budget | E4: Test dockets including contractor trigger | F4: Test first positive month | G4: Test lowest cash | H4: Test lowest cash month | I4: Test recommended opening cash | J4: Test break-even status
A5: High fee stress | B5: 10000 | C5: ='Gainsay drivers · Gainsay prici'!B10+('Gainsay drivers · Gainsay data-'!B5-'Gainsay drivers · Gainsay fixed'!B20)/12 -> 1593.9333 | D5: =CEILING('Gainsay drivers · Gainsay data-'!C5/'Gainsay drivers · Gainsay prici'!B8,1) -> 62 | E5: =IF(IF(IF(ISERROR('Gainsay drivers · Gainsay data-'!D5>='Gainsay drivers · Gainsay fixed'!B27),'Gainsay drivers · Gainsay data-'!D5>='Gainsay drivers · Gainsay fixed'!B27,IF(OR('Gainsay drivers · Gainsay data-'!D5="",'Gainsay drivers · Gainsay fixed'!B27=""),"",'Gainsay drivers · Gainsay data-'!D5>='Gainsay drivers · Gainsay fixed'!B27))="",FALSE(),IF(ISERROR('Gainsay drivers · Gainsay data-'!D5>='Gainsay drivers · Gainsay fixed'!B27),'Gainsay drivers · Gainsay data-'!D5>='Gainsay drivers · Gainsay fixed'!B27,IF(OR('Gainsay drivers · Gainsay data-'!D5="",'Gainsay drivers · Gainsay fixed'!B27=""),"",'Gainsay drivers · Gainsay data-'!D5>='Gainsay drivers · Gainsay fixed'!B27))),CEILING(('Gainsay drivers · Gainsay data-'!C5+'Gainsay drivers · Gainsay fixed'!B28+'Gainsay drivers · Gainsay fixed'!B30)/'Gainsay drivers · Gainsay prici'!B8,1),CEILING(('Gainsay drivers · Gainsay data-'!C5+'Gainsay drivers · Gainsay fixed'!B30)/'Gainsay drivers · Gainsay prici'!B8,1)) -> 77 | F5: =IF('Model inputs'!B688="","",EDATE(DATE(2026,10,1),IF((IF(AND('Model inputs'!B664="",'Model inputs'!B665="",'Model inputs'!B666="",'Model inputs'!B667="",'Model inputs'!B668="",'Model inputs'!B669="",'Model inputs'!B670="",'Model inputs'!B671="",'Model inputs'!B672="",'Model inputs'!B673="",'Model inputs'!B674="",'Model inputs'!B675="",'Model inputs'!B676="",'Model inputs'!B677="",'Model inputs'!B678="",'Model inputs'!B679="",'Model inputs'!B680="",'Model inputs'!B681="",'Model inputs'!B682="",'Model inputs'!B683="",'Model inputs'!B684="",'Model inputs'!B685="",'Model inputs'!B686="",'Model inputs'!B687=""),"",MIN('Model inputs'!B664,'Model inputs'!B665,'Model inputs'!B666,'Model inputs'!B667,'Model inputs'!B668,'Model inputs'!B669,'Model inputs'!B670,'Model inputs'!B671,'Model inputs'!B672,'Model inputs'!B673,'Model inputs'!B674,'Model inputs'!B675,'Model inputs'!B676,'Model inputs'!B677,'Model inputs'!B678,'Model inputs'!B679,'Model inputs'!B680,'Model inputs'!B681,'Model inputs'!B682,'Model inputs'!B683,'Model inputs'!B684,'Model inputs'!B685,'Model inputs'!B686,'Model inputs'!B687)))="",0,(IF(AND('Model inputs'!B664="",'Model inputs'!B665="",'Model inputs'!B666="",'Model inputs'!B667="",'Model inputs'!B668="",'Model inputs'!B669="",'Model inputs'!B670="",'Model inputs'!B671="",'Model inputs'!B672="",'Model inputs'!B673="",'Model inputs'!B674="",'Model inputs'!B675="",'Model inputs'!B676="",'Model inputs'!B677="",'Model inputs'!B678="",'Model inputs'!B679="",'Model inputs'!B680="",'Model inputs'!B681="",'Model inputs'!B682="",'Model inputs'!B683="",'Model inputs'!B684="",'Model inputs'!B685="",'Model inputs'!B686="",'Model inputs'!B687=""),"",MIN('Model inputs'!B664,'Model inputs'!B665,'Model inputs'!B666,'Model inputs'!B667,'Model inputs'!B668,'Model inputs'!B669,'Model inputs'!B670,'Model inputs'!B671,'Model inputs'!B672,'Model inputs'!B673,'Model inputs'!B674,'Model inputs'!B675,'Model inputs'!B676,'Model inputs'!B677,'Model inputs'!B678,'Model inputs'!B679,'Model inputs'!B680,'Model inputs'!B681,'Model inputs'!B682,'Model inputs'!B683,'Model inputs'!B684,'Model inputs'!B685,'Model inputs'!B686,'Model inputs'!B687))))-1)) | G5: =MIN('Gainsay economics · Gainsay dat'!B15,'Gainsay economics · Gainsay dat'!C15,'Gainsay economics · Gainsay dat'!D15,'Gainsay economics · Gainsay dat'!E15,'Gainsay economics · Gainsay dat'!F15,'Gainsay economics · Gainsay dat'!G15,'Gainsay economics · Gainsay dat'!H15,'Gainsay economics · Gainsay dat'!I15,'Gainsay economics · Gainsay dat'!J15,'Gainsay economics · Gainsay dat'!K15,'Gainsay economics · Gainsay dat'!L15,'Gainsay economics · Gainsay dat'!M15,'Gainsay economics · Gainsay dat'!N15,'Gainsay economics · Gainsay dat'!O15,'Gainsay economics · Gainsay dat'!P15) -> -7639.2578 | H5: =IF('Model inputs'!B761="","",EDATE(DATE(2026,10,1),IF((IF(AND('Model inputs'!B737="",'Model inputs'!B738="",'Model inputs'!B739="",'Model inputs'!B740="",'Model inputs'!B741="",'Model inputs'!B742="",'Model inputs'!B743="",'Model inputs'!B744="",'Model inputs'!B745="",'Model inputs'!B746="",'Model inputs'!B747="",'Model inputs'!B748="",'Model inputs'!B749="",'Model inputs'!B750="",'Model inputs'!B751="",'Model inputs'!B752="",'Model inputs'!B753="",'Model inputs'!B754="",'Model inputs'!B755="",'Model inputs'!B756="",'Model inputs'!B757="",'Model inputs'!B758="",'Model inputs'!B759="",'Model inputs'!B760=""),"",MIN('Model inputs'!B737,'Model inputs'!B738,'Model inputs'!B739,'Model inputs'!B740,'Model inputs'!B741,'Model inputs'!B742,'Model inputs'!B743,'Model inputs'!B744,'Model inputs'!B745,'Model inputs'!B746,'Model inputs'!B747,'Model inputs'!B748,'Model inputs'!B749,'Model inputs'!B750,'Model inputs'!B751,'Model inputs'!B752,'Model inputs'!B753,'Model inputs'!B754,'Model inputs'!B755,'Model inputs'!B756,'Model inputs'!B757,'Model inputs'!B758,'Model inputs'!B759,'Model inputs'!B760)))="",0,(IF(AND('Model inputs'!B737="",'Model inputs'!B738="",'Model inputs'!B739="",'Model inputs'!B740="",'Model inputs'!B741="",'Model inputs'!B742="",'Model inputs'!B743="",'Model inputs'!B744="",'Model inputs'!B745="",'Model inputs'!B746="",'Model inputs'!B747="",'Model inputs'!B748="",'Model inputs'!B749="",'Model inputs'!B750="",'Model inputs'!B751="",'Model inputs'!B752="",'Model inputs'!B753="",'Model inputs'!B754="",'Model inputs'!B755="",'Model inputs'!B756="",'Model inputs'!B757="",'Model inputs'!B758="",'Model inputs'!B759="",'Model inputs'!B760=""),"",MIN('Model inputs'!B737,'Model inputs'!B738,'Model inputs'!B739,'Model inputs'!B740,'Model inputs'!B741,'Model inputs'!B742,'Model inputs'!B743,'Model inputs'!B744,'Model inputs'!B745,'Model inputs'!B746,'Model inputs'!B747,'Model inputs'!B748,'Model inputs'!B749,'Model inputs'!B750,'Model inputs'!B751,'Model inputs'!B752,'Model inputs'!B753,'Model inputs'!B754,'Model inputs'!B755,'Model inputs'!B756,'Model inputs'!B757,'Model inputs'!B758,'Model inputs'!B759,'Model inputs'!B760))))-1)) -> 46722 | I5: =CEILING('Gainsay drivers · Gainsay fixed'!B21+'Gainsay drivers · Gainsay fixed'!B31*('Gainsay drivers · Gainsay data-'!C5+'Gainsay drivers · Gainsay fixed'!B30)-'Gainsay drivers · Gainsay data-'!G5,'Gainsay drivers · Gainsay fixed'!B33) -> 17500 | J5: =IF('Gainsay drivers · Gainsay data-'!F5="","Not reached through December 2027","Reached") -> Not reached through December 2027
A6: Illustrative fee | B6: 3000 | C6: ='Gainsay drivers · Gainsay prici'!B10+('Gainsay drivers · Gainsay data-'!B6-'Gainsay drivers · Gainsay fixed'!B20)/12 -> 1010.6 | D6: =CEILING('Gainsay drivers · Gainsay data-'!C6/'Gainsay drivers · Gainsay prici'!B8,1) -> 39 | E6: =IF(IF(IF(ISERROR('Gainsay drivers · Gainsay data-'!D6>='Gainsay drivers · Gainsay fixed'!B27),'Gainsay drivers · Gainsay data-'!D6>='Gainsay drivers · Gainsay fixed'!B27,IF(OR('Gainsay drivers · Gainsay data-'!D6="",'Gainsay drivers · Gainsay fixed'!B27=""),"",'Gainsay drivers · Gainsay data-'!D6>='Gainsay drivers · Gainsay fixed'!B27))="",FALSE(),IF(ISERROR('Gainsay drivers · Gainsay data-'!D6>='Gainsay drivers · Gainsay fixed'!B27),'Gainsay drivers · Gainsay data-'!D6>='Gainsay drivers · Gainsay fixed'!B27,IF(OR('Gainsay drivers · Gainsay data-'!D6="",'Gainsay drivers · Gainsay fixed'!B27=""),"",'Gainsay drivers · Gainsay data-'!D6>='Gainsay drivers · Gainsay fixed'!B27))),CEILING(('Gainsay drivers · Gainsay data-'!C6+'Gainsay drivers · Gainsay fixed'!B28+'Gainsay drivers · Gainsay fixed'!B30)/'Gainsay drivers · Gainsay prici'!B8,1),CEILING(('Gainsay drivers · Gainsay data-'!C6+'Gainsay drivers · Gainsay fixed'!B30)/'Gainsay drivers · Gainsay prici'!B8,1)) -> 39 | F6: =IF('Model inputs'!B825="","",EDATE(DATE(2026,10,1),IF((IF(AND('Model inputs'!B801="",'Model inputs'!B802="",'Model inputs'!B803="",'Model inputs'!B804="",'Model inputs'!B805="",'Model inputs'!B806="",'Model inputs'!B807="",'Model inputs'!B808="",'Model inputs'!B809="",'Model inputs'!B810="",'Model inputs'!B811="",'Model inputs'!B812="",'Model inputs'!B813="",'Model inputs'!B814="",'Model inputs'!B815="",'Model inputs'!B816="",'Model inputs'!B817="",'Model inputs'!B818="",'Model inputs'!B819="",'Model inputs'!B820="",'Model inputs'!B821="",'Model inputs'!B822="",'Model inputs'!B823="",'Model inputs'!B824=""),"",MIN('Model inputs'!B801,'Model inputs'!B802,'Model inputs'!B803,'Model inputs'!B804,'Model inputs'!B805,'Model inputs'!B806,'Model inputs'!B807,'Model inputs'!B808,'Model inputs'!B809,'Model inputs'!B810,'Model inputs'!B811,'Model inputs'!B812,'Model inputs'!B813,'Model inputs'!B814,'Model inputs'!B815,'Model inputs'!B816,'Model inputs'!B817,'Model inputs'!B818,'Model inputs'!B819,'Model inputs'!B820,'Model inputs'!B821,'Model inputs'!B822,'Model inputs'!B823,'Model inputs'!B824)))="",0,(IF(AND('Model inputs'!B801="",'Model inputs'!B802="",'Model inputs'!B803="",'Model inputs'!B804="",'Model inputs'!B805="",'Model inputs'!B806="",'Model inputs'!B807="",'Model inputs'!B808="",'Model inputs'!B809="",'Model inputs'!B810="",'Model inputs'!B811="",'Model inputs'!B812="",'Model inputs'!B813="",'Model inputs'!B814="",'Model inputs'!B815="",'Model inputs'!B816="",'Model inputs'!B817="",'Model inputs'!B818="",'Model inputs'!B819="",'Model inputs'!B820="",'Model inputs'!B821="",'Model inputs'!B822="",'Model inputs'!B823="",'Model inputs'!B824=""),"",MIN('Model inputs'!B801,'Model inputs'!B802,'Model inputs'!B803,'Model inputs'!B804,'Model inputs'!B805,'Model inputs'!B806,'Model inputs'!B807,'Model inputs'!B808,'Model inputs'!B809,'Model inputs'!B810,'Model inputs'!B811,'Model inputs'!B812,'Model inputs'!B813,'Model inputs'!B814,'Model inputs'!B815,'Model inputs'!B816,'Model inputs'!B817,'Model inputs'!B818,'Model inputs'!B819,'Model inputs'!B820,'Model inputs'!B821,'Model inputs'!B822,'Model inputs'!B823,'Model inputs'!B824))))-1)) -> 46600 | G6: =MIN('Gainsay economics · Gainsay dat'!B16,'Gainsay economics · Gainsay dat'!C16,'Gainsay economics · Gainsay dat'!D16,'Gainsay economics · Gainsay dat'!E16,'Gainsay economics · Gainsay dat'!F16,'Gainsay economics · Gainsay dat'!G16,'Gainsay economics · Gainsay dat'!H16,'Gainsay economics · Gainsay dat'!I16,'Gainsay economics · Gainsay dat'!J16,'Gainsay economics · Gainsay dat'!K16,'Gainsay economics · Gainsay dat'!L16,'Gainsay economics · Gainsay dat'!M16,'Gainsay economics · Gainsay dat'!N16,'Gainsay economics · Gainsay dat'!O16,'Gainsay economics · Gainsay dat'!P16) -> -53.199018 | H6: =IF('Model inputs'!B898="","",EDATE(DATE(2026,10,1),IF((IF(AND('Model inputs'!B874="",'Model inputs'!B875="",'Model inputs'!B876="",'Model inputs'!B877="",'Model inputs'!B878="",'Model inputs'!B879="",'Model inputs'!B880="",'Model inputs'!B881="",'Model inputs'!B882="",'Model inputs'!B883="",'Model inputs'!B884="",'Model inputs'!B885="",'Model inputs'!B886="",'Model inputs'!B887="",'Model inputs'!B888="",'Model inputs'!B889="",'Model inputs'!B890="",'Model inputs'!B891="",'Model inputs'!B892="",'Model inputs'!B893="",'Model inputs'!B894="",'Model inputs'!B895="",'Model inputs'!B896="",'Model inputs'!B897=""),"",MIN('Model inputs'!B874,'Model inputs'!B875,'Model inputs'!B876,'Model inputs'!B877,'Model inputs'!B878,'Model inputs'!B879,'Model inputs'!B880,'Model inputs'!B881,'Model inputs'!B882,'Model inputs'!B883,'Model inputs'!B884,'Model inputs'!B885,'Model inputs'!B886,'Model inputs'!B887,'Model inputs'!B888,'Model inputs'!B889,'Model inputs'!B890,'Model inputs'!B891,'Model inputs'!B892,'Model inputs'!B893,'Model inputs'!B894,'Model inputs'!B895,'Model inputs'!B896,'Model inputs'!B897)))="",0,(IF(AND('Model inputs'!B874="",'Model inputs'!B875="",'Model inputs'!B876="",'Model inputs'!B877="",'Model inputs'!B878="",'Model inputs'!B879="",'Model inputs'!B880="",'Model inputs'!B881="",'Model inputs'!B882="",'Model inputs'!B883="",'Model inputs'!B884="",'Model inputs'!B885="",'Model inputs'!B886="",'Model inputs'!B887="",'Model inputs'!B888="",'Model inputs'!B889="",'Model inputs'!B890="",'Model inputs'!B891="",'Model inputs'!B892="",'Model inputs'!B893="",'Model inputs'!B894="",'Model inputs'!B895="",'Model inputs'!B896="",'Model inputs'!B897=""),"",MIN('Model inputs'!B874,'Model inputs'!B875,'Model inputs'!B876,'Model inputs'!B877,'Model inputs'!B878,'Model inputs'!B879,'Model inputs'!B880,'Model inputs'!B881,'Model inputs'!B882,'Model inputs'!B883,'Model inputs'!B884,'Model inputs'!B885,'Model inputs'!B886,'Model inputs'!B887,'Model inputs'!B888,'Model inputs'!B889,'Model inputs'!B890,'Model inputs'!B891,'Model inputs'!B892,'Model inputs'!B893,'Model inputs'!B894,'Model inputs'!B895,'Model inputs'!B896,'Model inputs'!B897))))-1)) -> 46569 | I6: =CEILING('Gainsay drivers · Gainsay fixed'!B21+'Gainsay drivers · Gainsay fixed'!B31*('Gainsay drivers · Gainsay data-'!C6+'Gainsay drivers · Gainsay fixed'!B30)-'Gainsay drivers · Gainsay data-'!G6,'Gainsay drivers · Gainsay fixed'!B33) -> 8500 | J6: =IF('Gainsay drivers · Gainsay data-'!F6="","Not reached through December 2027","Reached") -> Reached
A7: No fee sensitivity only | B7: 0 | C7: ='Gainsay drivers · Gainsay prici'!B10+('Gainsay drivers · Gainsay data-'!B7-'Gainsay drivers · Gainsay fixed'!B20)/12 -> 760.6 | D7: =CEILING('Gainsay drivers · Gainsay data-'!C7/'Gainsay drivers · Gainsay prici'!B8,1) -> 30 | E7: =IF(IF(IF(ISERROR('Gainsay drivers · Gainsay data-'!D7>='Gainsay drivers · Gainsay fixed'!B27),'Gainsay drivers · Gainsay data-'!D7>='Gainsay drivers · Gainsay fixed'!B27,IF(OR('Gainsay drivers · Gainsay data-'!D7="",'Gainsay drivers · Gainsay fixed'!B27=""),"",'Gainsay drivers · Gainsay data-'!D7>='Gainsay drivers · Gainsay fixed'!B27))="",FALSE(),IF(ISERROR('Gainsay drivers · Gainsay data-'!D7>='Gainsay drivers · Gainsay fixed'!B27),'Gainsay drivers · Gainsay data-'!D7>='Gainsay drivers · Gainsay fixed'!B27,IF(OR('Gainsay drivers · Gainsay data-'!D7="",'Gainsay drivers · Gainsay fixed'!B27=""),"",'Gainsay drivers · Gainsay data-'!D7>='Gainsay drivers · Gainsay fixed'!B27))),CEILING(('Gainsay drivers · Gainsay data-'!C7+'Gainsay drivers · Gainsay fixed'!B28+'Gainsay drivers · Gainsay fixed'!B30)/'Gainsay drivers · Gainsay prici'!B8,1),CEILING(('Gainsay drivers · Gainsay data-'!C7+'Gainsay drivers · Gainsay fixed'!B30)/'Gainsay drivers · Gainsay prici'!B8,1)) -> 30 | F7: =IF('Model inputs'!B962="","",EDATE(DATE(2026,10,1),IF((IF(AND('Model inputs'!B938="",'Model inputs'!B939="",'Model inputs'!B940="",'Model inputs'!B941="",'Model inputs'!B942="",'Model inputs'!B943="",'Model inputs'!B944="",'Model inputs'!B945="",'Model inputs'!B946="",'Model inputs'!B947="",'Model inputs'!B948="",'Model inputs'!B949="",'Model inputs'!B950="",'Model inputs'!B951="",'Model inputs'!B952="",'Model inputs'!B953="",'Model inputs'!B954="",'Model inputs'!B955="",'Model inputs'!B956="",'Model inputs'!B957="",'Model inputs'!B958="",'Model inputs'!B959="",'Model inputs'!B960="",'Model inputs'!B961=""),"",MIN('Model inputs'!B938,'Model inputs'!B939,'Model inputs'!B940,'Model inputs'!B941,'Model inputs'!B942,'Model inputs'!B943,'Model inputs'!B944,'Model inputs'!B945,'Model inputs'!B946,'Model inputs'!B947,'Model inputs'!B948,'Model inputs'!B949,'Model inputs'!B950,'Model inputs'!B951,'Model inputs'!B952,'Model inputs'!B953,'Model inputs'!B954,'Model inputs'!B955,'Model inputs'!B956,'Model inputs'!B957,'Model inputs'!B958,'Model inputs'!B959,'Model inputs'!B960,'Model inputs'!B961)))="",0,(IF(AND('Model inputs'!B938="",'Model inputs'!B939="",'Model inputs'!B940="",'Model inputs'!B941="",'Model inputs'!B942="",'Model inputs'!B943="",'Model inputs'!B944="",'Model inputs'!B945="",'Model inputs'!B946="",'Model inputs'!B947="",'Model inputs'!B948="",'Model inputs'!B949="",'Model inputs'!B950="",'Model inputs'!B951="",'Model inputs'!B952="",'Model inputs'!B953="",'Model inputs'!B954="",'Model inputs'!B955="",'Model inputs'!B956="",'Model inputs'!B957="",'Model inputs'!B958="",'Model inputs'!B959="",'Model inputs'!B960="",'Model inputs'!B961=""),"",MIN('Model inputs'!B938,'Model inputs'!B939,'Model inputs'!B940,'Model inputs'!B941,'Model inputs'!B942,'Model inputs'!B943,'Model inputs'!B944,'Model inputs'!B945,'Model inputs'!B946,'Model inputs'!B947,'Model inputs'!B948,'Model inputs'!B949,'Model inputs'!B950,'Model inputs'!B951,'Model inputs'!B952,'Model inputs'!B953,'Model inputs'!B954,'Model inputs'!B955,'Model inputs'!B956,'Model inputs'!B957,'Model inputs'!B958,'Model inputs'!B959,'Model inputs'!B960,'Model inputs'!B961))))-1)) -> 46508 | G7: =MIN('Gainsay economics · Gainsay dat'!B17,'Gainsay economics · Gainsay dat'!C17,'Gainsay economics · Gainsay dat'!D17,'Gainsay economics · Gainsay dat'!E17,'Gainsay economics · Gainsay dat'!F17,'Gainsay economics · Gainsay dat'!G17,'Gainsay economics · Gainsay dat'!H17,'Gainsay economics · Gainsay dat'!I17,'Gainsay economics · Gainsay dat'!J17,'Gainsay economics · Gainsay dat'!K17,'Gainsay economics · Gainsay dat'!L17,'Gainsay economics · Gainsay dat'!M17,'Gainsay economics · Gainsay dat'!N17,'Gainsay economics · Gainsay dat'!O17,'Gainsay economics · Gainsay dat'!P17) -> 2074.2752 | H7: =IF('Model inputs'!B1035="","",EDATE(DATE(2026,10,1),IF((IF(AND('Model inputs'!B1011="",'Model inputs'!B1012="",'Model inputs'!B1013="",'Model inputs'!B1014="",'Model inputs'!B1015="",'Model inputs'!B1016="",'Model inputs'!B1017="",'Model inputs'!B1018="",'Model inputs'!B1019="",'Model inputs'!B1020="",'Model inputs'!B1021="",'Model inputs'!B1022="",'Model inputs'!B1023="",'Model inputs'!B1024="",'Model inputs'!B1025="",'Model inputs'!B1026="",'Model inputs'!B1027="",'Model inputs'!B1028="",'Model inputs'!B1029="",'Model inputs'!B1030="",'Model inputs'!B1031="",'Model inputs'!B1032="",'Model inputs'!B1033="",'Model inputs'!B1034=""),"",MIN('Model inputs'!B1011,'Model inputs'!B1012,'Model inputs'!B1013,'Model inputs'!B1014,'Model inputs'!B1015,'Model inputs'!B1016,'Model inputs'!B1017,'Model inputs'!B1018,'Model inputs'!B1019,'Model inputs'!B1020,'Model inputs'!B1021,'Model inputs'!B1022,'Model inputs'!B1023,'Model inputs'!B1024,'Model inputs'!B1025,'Model inputs'!B1026,'Model inputs'!B1027,'Model inputs'!B1028,'Model inputs'!B1029,'Model inputs'!B1030,'Model inputs'!B1031,'Model inputs'!B1032,'Model inputs'!B1033,'Model inputs'!B1034)))="",0,(IF(AND('Model inputs'!B1011="",'Model inputs'!B1012="",'Model inputs'!B1013="",'Model inputs'!B1014="",'Model inputs'!B1015="",'Model inputs'!B1016="",'Model inputs'!B1017="",'Model inputs'!B1018="",'Model inputs'!B1019="",'Model inputs'!B1020="",'Model inputs'!B1021="",'Model inputs'!B1022="",'Model inputs'!B1023="",'Model inputs'!B1024="",'Model inputs'!B1025="",'Model inputs'!B1026="",'Model inputs'!B1027="",'Model inputs'!B1028="",'Model inputs'!B1029="",'Model inputs'!B1030="",'Model inputs'!B1031="",'Model inputs'!B1032="",'Model inputs'!B1033="",'Model inputs'!B1034=""),"",MIN('Model inputs'!B1011,'Model inputs'!B1012,'Model inputs'!B1013,'Model inputs'!B1014,'Model inputs'!B1015,'Model inputs'!B1016,'Model inputs'!B1017,'Model inputs'!B1018,'Model inputs'!B1019,'Model inputs'!B1020,'Model inputs'!B1021,'Model inputs'!B1022,'Model inputs'!B1023,'Model inputs'!B1024,'Model inputs'!B1025,'Model inputs'!B1026,'Model inputs'!B1027,'Model inputs'!B1028,'Model inputs'!B1029,'Model inputs'!B1030,'Model inputs'!B1031,'Model inputs'!B1032,'Model inputs'!B1033,'Model inputs'!B1034))))-1)) -> 46478 | I7: =CEILING('Gainsay drivers · Gainsay fixed'!B21+'Gainsay drivers · Gainsay fixed'!B31*('Gainsay drivers · Gainsay data-'!C7+'Gainsay drivers · Gainsay fixed'!B30)-'Gainsay drivers · Gainsay data-'!G7,'Gainsay drivers · Gainsay fixed'!B33) -> 5500 | J7: =IF('Gainsay drivers · Gainsay data-'!F7="","Not reached through December 2027","Reached") -> Reached

Sheet Gainsay economics · Gainsay ope
A1: Gainsay economics · Gainsay operating forecast
A2: Financial model (3 pages) · Main Scenario
A4: Variable / dimension | B4: 2026-10 | C4: 2026-11 | D4: 2026-12 | E4: 2027-01 | F4: 2027-02 | G4: 2027-03 | H4: 2027-04 | I4: 2027-05 | J4: 2027-06 | K4: 2027-07 | L4: 2027-08 | M4: 2027-09 | N4: 2027-10 | O4: 2027-11 | P4: 2027-12
A5: Active dockets | B5: ='Model inputs'!J6*(1-'Gainsay drivers · Gainsay deman'!B7)+'Gainsay drivers · Gainsay deman'!B5 -> 3 | C5: ='Gainsay economics · Gainsay ope'!B5*(1-'Gainsay drivers · Gainsay deman'!C7)+'Gainsay drivers · Gainsay deman'!C5 -> 6.06 | D5: ='Gainsay economics · Gainsay ope'!C5*(1-'Gainsay drivers · Gainsay deman'!D7)+'Gainsay drivers · Gainsay deman'!D5 -> 9.1857 | E5: ='Gainsay economics · Gainsay ope'!D5*(1-'Gainsay drivers · Gainsay deman'!E7)+'Gainsay drivers · Gainsay deman'!E5 -> 12.383004 | F5: ='Gainsay economics · Gainsay ope'!E5*(1-'Gainsay drivers · Gainsay deman'!F7)+'Gainsay drivers · Gainsay deman'!F5 -> 15.658033 | G5: ='Gainsay economics · Gainsay ope'!F5*(1-'Gainsay drivers · Gainsay deman'!G7)+'Gainsay drivers · Gainsay deman'!G5 -> 19.017136 | H5: ='Gainsay economics · Gainsay ope'!G5*(1-'Gainsay drivers · Gainsay deman'!H7)+'Gainsay drivers · Gainsay deman'!H5 -> 22.466909 | I5: ='Gainsay economics · Gainsay ope'!H5*(1-'Gainsay drivers · Gainsay deman'!I7)+'Gainsay drivers · Gainsay deman'!I5 -> 26.014203 | J5: ='Gainsay economics · Gainsay ope'!I5*(1-'Gainsay drivers · Gainsay deman'!J7)+'Gainsay drivers · Gainsay deman'!J5 -> 29.666143 | ... P5: ='Gainsay economics · Gainsay ope'!O5*(1-'Gainsay drivers · Gainsay deman'!P7)+'Gainsay drivers · Gainsay deman'!P5 -> 54.212887
A6: Brief checks sold | B6: ='Gainsay drivers · Gainsay deman'!B8 -> 10 | C6: ='Gainsay economics · Gainsay ope'!B6*(1+'Gainsay drivers · Gainsay deman'!C9) -> 10.5 | D6: ='Gainsay economics · Gainsay ope'!C6*(1+'Gainsay drivers · Gainsay deman'!D9) -> 11.025 | E6: ='Gainsay economics · Gainsay ope'!D6*(1+'Gainsay drivers · Gainsay deman'!E9) -> 11.57625 | F6: ='Gainsay economics · Gainsay ope'!E6*(1+'Gainsay drivers · Gainsay deman'!F9) -> 12.155062 | G6: ='Gainsay economics · Gainsay ope'!F6*(1+'Gainsay drivers · Gainsay deman'!G9) -> 12.762816 | H6: ='Gainsay economics · Gainsay ope'!G6*(1+'Gainsay drivers · Gainsay deman'!H9) -> 13.400956 | I6: ='Gainsay economics · Gainsay ope'!H6*(1+'Gainsay drivers · Gainsay deman'!I9) -> 14.071004 | J6: ='Gainsay economics · Gainsay ope'!I6*(1+'Gainsay drivers · Gainsay deman'!J9) -> 14.774554 | ... P6: ='Gainsay economics · Gainsay ope'!O6*(1+'Gainsay drivers · Gainsay deman'!P9) -> 19.799316
A7: Gainsay revenue | B7: ='Gainsay economics · Gainsay ope'!B16+'Gainsay economics · Gainsay ope'!B17 -> 177 | C7: ='Gainsay economics · Gainsay ope'!C16+'Gainsay economics · Gainsay ope'!C17 -> 270.24 | D7: ='Gainsay economics · Gainsay ope'!D16+'Gainsay economics · Gainsay ope'!D17 -> 365.6103 | E7: ='Gainsay economics · Gainsay ope'!E16+'Gainsay economics · Gainsay ope'!E17 -> 463.29337 | F7: ='Gainsay economics · Gainsay ope'!F16+'Gainsay economics · Gainsay ope'!F17 -> 563.47851 | G7: ='Gainsay economics · Gainsay ope'!G16+'Gainsay economics · Gainsay ope'!G17 -> 666.36229 | H7: ='Gainsay economics · Gainsay ope'!H16+'Gainsay economics · Gainsay ope'!H17 -> 772.14897 | I7: ='Gainsay economics · Gainsay ope'!I16+'Gainsay economics · Gainsay ope'!I17 -> 881.05093 | ... P7: ='Gainsay economics · Gainsay ope'!P16+'Gainsay economics · Gainsay ope'!P17 -> 1750.3676
A8: Card fees | B8: =IF('Gainsay economics · Gainsay ope'!B24="","",'Gainsay economics · Gainsay ope'!B24) -> 9.033 | C8: =IF('Gainsay economics · Gainsay ope'!C24="","",'Gainsay economics · Gainsay ope'!C24) -> 12.80496 | D8: =IF('Gainsay economics · Gainsay ope'!D24="","",'Gainsay economics · Gainsay ope'!D24) -> 16.665909 | E8: =IF('Gainsay economics · Gainsay ope'!E24="","",'Gainsay economics · Gainsay ope'!E24) -> 20.623284 | F8: =IF('Gainsay economics · Gainsay ope'!F24="","",'Gainsay economics · Gainsay ope'!F24) -> 24.684805 | G8: =IF('Gainsay economics · Gainsay ope'!G24="","",'Gainsay economics · Gainsay ope'!G24) -> 28.858492 | H8: =IF('Gainsay economics · Gainsay ope'!H24="","",'Gainsay economics · Gainsay ope'!H24) -> 33.15268 | I8: =IF('Gainsay economics · Gainsay ope'!I24="","",'Gainsay economics · Gainsay ope'!I24) -> 37.576039 | ... P8: =IF('Gainsay economics · Gainsay ope'!P24="","",'Gainsay economics · Gainsay ope'!P24) -> 72.96432
A9: Claude cost | B9: ='Gainsay economics · Gainsay ope'!B22+'Gainsay economics · Gainsay ope'!B23 -> 30.16 | C9: ='Gainsay economics · Gainsay ope'!C22+'Gainsay economics · Gainsay ope'!C23 -> 36.1842 | D9: ='Gainsay economics · Gainsay ope'!D22+'Gainsay economics · Gainsay ope'!D23 -> 42.350724 | E9: ='Gainsay economics · Gainsay ope'!E22+'Gainsay economics · Gainsay ope'!E23 -> 48.671455 | F9: ='Gainsay economics · Gainsay ope'!F22+'Gainsay economics · Gainsay ope'!F23 -> 55.158726 | G9: ='Gainsay economics · Gainsay ope'!G22+'Gainsay economics · Gainsay ope'!G23 -> 61.82535 | H9: ='Gainsay economics · Gainsay ope'!H22+'Gainsay economics · Gainsay ope'!H23 -> 68.684645 | I9: ='Gainsay economics · Gainsay ope'!I22+'Gainsay economics · Gainsay ope'!I23 -> 75.750464 | ... P9: ='Gainsay economics · Gainsay ope'!P22+'Gainsay economics · Gainsay ope'!P23 -> 132.28483
A10: Fixed costs monthly reserved | B10: ='Gainsay drivers · Gainsay prici'!B10-'Gainsay economics · Gainsay ope'!B23+'Gainsay economics · Gainsay ope'!B27+'Gainsay economics · Gainsay ope'!B49 -> 995 | C10: ='Gainsay drivers · Gainsay prici'!B10-'Gainsay economics · Gainsay ope'!C23+'Gainsay economics · Gainsay ope'!C27+'Gainsay economics · Gainsay ope'!C49 -> 995 | D10: ='Gainsay drivers · Gainsay prici'!B10-'Gainsay economics · Gainsay ope'!D23+'Gainsay economics · Gainsay ope'!D27+'Gainsay economics · Gainsay ope'!D49 -> 995 | E10: ='Gainsay drivers · Gainsay prici'!B10-'Gainsay economics · Gainsay ope'!E23+'Gainsay economics · Gainsay ope'!E27+'Gainsay economics · Gainsay ope'!E49 -> 995 | F10: ='Gainsay drivers · Gainsay prici'!B10-'Gainsay economics · Gainsay ope'!F23+'Gainsay economics · Gainsay ope'!F27+'Gainsay economics · Gainsay ope'!F49 -> 995 | G10: ='Gainsay drivers · Gainsay prici'!B10-'Gainsay economics · Gainsay ope'!G23+'Gainsay economics · Gainsay ope'!G27+'Gainsay economics · Gainsay ope'!G49 -> 995 | H10: ='Gainsay drivers · Gainsay prici'!B10-'Gainsay economics · Gainsay ope'!H23+'Gainsay economics · Gainsay ope'!H27+'Gainsay economics · Gainsay ope'!H49 -> 995 | I10: ='Gainsay drivers · Gainsay prici'!B10-'Gainsay economics · Gainsay ope'!I23+'Gainsay economics · Gainsay ope'!I27+'Gainsay economics · Gainsay ope'!I49 -> 995 | J10: ='Gainsay drivers · Gainsay prici'!B10-'Gainsay economics · Gainsay ope'!J23+'Gainsay economics · Gainsay ope'!J27+'Gainsay economics · Gainsay ope'!J49 -> 995 | K10: ='Gainsay drivers · Gainsay prici'!B10-'Gainsay economics · Gainsay ope'!K23+'Gainsay economics · Gainsay ope'!K27+'Gainsay economics · Gainsay ope'!K49 -> 995 | L10: ='Gainsay drivers · Gainsay prici'!B10-'Gainsay economics · Gainsay ope'!L23+'Gainsay economics · Gainsay ope'!L27+'Gainsay economics · Gainsay ope'!L49 -> 995 | M10: ='Gainsay drivers · Gainsay prici'!B10-'Gainsay economics · Gainsay ope'!M23+'Gainsay economics · Gainsay ope'!M27+'Gainsay economics · Gainsay ope'!M49 -> 995 | N10: ='Gainsay drivers · Gainsay prici'!B10-'Gainsay economics · Gainsay ope'!N23+'Gainsay economics · Gainsay ope'!N27+'Gainsay economics · Gainsay ope'!N49 -> 995 | O10: ='Gainsay drivers · Gainsay prici'!B10-'Gainsay economics · Gainsay ope'!O23+'Gainsay economics · Gainsay ope'!O27+'Gainsay economics · Gainsay ope'!O49 -> 995 | P10: ='Gainsay drivers · Gainsay prici'!B10-'Gainsay economics · Gainsay ope'!P23+'Gainsay economics · Gainsay ope'!P27+'Gainsay economics · Gainsay ope'!P49 -> 1395
A11: Monthly result | B11: ='Gainsay economics · Gainsay ope'!B7-'Gainsay economics · Gainsay ope'!B8-'Gainsay economics · Gainsay ope'!B9-'Gainsay economics · Gainsay ope'!B10 -> -857.193 | C11: ='Gainsay economics · Gainsay ope'!C7-'Gainsay economics · Gainsay ope'!C8-'Gainsay economics · Gainsay ope'!C9-'Gainsay economics · Gainsay ope'!C10 -> -773.74916 | D11: ='Gainsay economics · Gainsay ope'!D7-'Gainsay economics · Gainsay ope'!D8-'Gainsay economics · Gainsay ope'!D9-'Gainsay economics · Gainsay ope'!D10 -> -688.40633 | E11: ='Gainsay economics · Gainsay ope'!E7-'Gainsay economics · Gainsay ope'!E8-'Gainsay economics · Gainsay ope'!E9-'Gainsay economics · Gainsay ope'!E10 -> -601.00137 | F11: ='Gainsay economics · Gainsay ope'!F7-'Gainsay economics · Gainsay ope'!F8-'Gainsay economics · Gainsay ope'!F9-'Gainsay economics · Gainsay ope'!F10 -> -511.36502 | G11: ='Gainsay economics · Gainsay ope'!G7-'Gainsay economics · Gainsay ope'!G8-'Gainsay economics · Gainsay ope'!G9-'Gainsay economics · Gainsay ope'!G10 -> -419.32155 | H11: ='Gainsay economics · Gainsay ope'!H7-'Gainsay economics · Gainsay ope'!H8-'Gainsay economics · Gainsay ope'!H9-'Gainsay economics · Gainsay ope'!H10 -> -324.68835 | I11: ='Gainsay economics · Gainsay ope'!I7-'Gainsay economics · Gainsay ope'!I8-'Gainsay economics · Gainsay ope'!I9-'Gainsay economics · Gainsay ope'!I10 -> -227.27557 | ... P11: ='Gainsay economics · Gainsay ope'!P7-'Gainsay economics · Gainsay ope'!P8-'Gainsay economics · Gainsay ope'!P9-'Gainsay economics · Gainsay ope'!P10 -> 150.11842
A12: Cumulative cash monthly reserved | B12: =IF(IF(DATE(2026,10,1)=DATE(2026,10,1),'Gainsay drivers · Gainsay fixed'!B21-'Gainsay drivers · Gainsay fixed'!B22,IF('Model inputs'!J32="","",'Model inputs'!J32))="",0,IF(DATE(2026,10,1)=DATE(2026,10,1),'Gainsay drivers · Gainsay fixed'!B21-'Gainsay drivers · Gainsay fixed'!B22,IF('Model inputs'!J32="","",'Model inputs'!J32)))+'Gainsay economics · Gainsay ope'!B11 -> 3642.807 | C12: =IF(IF(DATE(2026,11,1)=DATE(2026,10,1),'Gainsay drivers · Gainsay fixed'!B21-'Gainsay drivers · Gainsay fixed'!B22,IF('Gainsay economics · Gainsay ope'!B12="","",'Gainsay economics · Gainsay ope'!B12))="",0,IF(DATE(2026,11,1)=DATE(2026,10,1),'Gainsay drivers · Gainsay fixed'!B21-'Gainsay drivers · Gainsay fixed'!B22,IF('Gainsay economics · Gainsay ope'!B12="","",'Gainsay economics · Gainsay ope'!B12)))+'Gainsay economics · Gainsay ope'!C11 -> 2869.0578 | D12: =IF(IF(DATE(2026,12,1)=DATE(2026,10,1),'Gainsay drivers · Gainsay fixed'!B21-'Gainsay drivers · Gainsay fixed'!B22,IF('Gainsay economics · Gainsay ope'!C12="","",'Gainsay economics · Gainsay ope'!C12))="",0,IF(DATE(2026,12,1)=DATE(2026,10,1),'Gainsay drivers · Gainsay fixed'!B21-'Gainsay drivers · Gainsay fixed'!B22,IF('Gainsay economics · Gainsay ope'!C12="","",'Gainsay economics · Gainsay ope'!C12)))+'Gainsay economics · Gainsay ope'!D11 -> 2180.6515 | E12: =IF(IF(DATE(2027,1,1)=DATE(2026,10,1),'Gainsay drivers · Gainsay fixed'!B21-'Gainsay drivers · Gainsay fixed'!B22,IF('Gainsay economics · Gainsay ope'!D12="","",'Gainsay economics · Gainsay ope'!D12))="",0,IF(DATE(2027,1,1)=DATE(2026,10,1),'Gainsay drivers · Gainsay fixed'!B21-'Gainsay drivers · Gainsay fixed'!B22,IF('Gainsay economics · Gainsay ope'!D12="","",'Gainsay economics · Gainsay ope'!D12)))+'Gainsay economics · Gainsay ope'!E11 -> 1579.6501 | F12: =IF(IF(DATE(2027,2,1)=DATE(2026,10,1),'Gainsay drivers · Gainsay fixed'!B21-'Gainsay drivers · Gainsay fixed'!B22,IF('Gainsay economics · Gainsay ope'!E12="","",'Gainsay economics · Gainsay ope'!E12))="",0,IF(DATE(2027,2,1)=DATE(2026,10,1),'Gainsay drivers · Gainsay fixed'!B21-'Gainsay drivers · Gainsay fixed'!B22,IF('Gainsay economics · Gainsay ope'!E12="","",'Gainsay economics · Gainsay ope'!E12)))+'Gainsay economics · Gainsay ope'!F11 -> 1068.2851 | G12: =IF(IF(DATE(2027,3,1)=DATE(2026,10,1),'Gainsay drivers · Gainsay fixed'!B21-'Gainsay drivers · Gainsay fixed'!B22,IF('Gainsay economics · Gainsay ope'!F12="","",'Gainsay economics · Gainsay ope'!F12))="",0,IF(DATE(2027,3,1)=DATE(2026,10,1),'Gainsay drivers · Gainsay fixed'!B21-'Gainsay drivers · Gainsay fixed'!B22,IF('Gainsay economics · Gainsay ope'!F12="","",'Gainsay economics · Gainsay ope'!F12)))+'Gainsay economics · Gainsay ope'!G11 -> 648.96356 | H12: =IF(IF(DATE(2027,4,1)=DATE(2026,10,1),'Gainsay drivers · Gainsay fixed'!B21-'Gainsay drivers · Gainsay fixed'!B22,IF('Gainsay economics · Gainsay ope'!G12="","",'Gainsay economics · Gainsay ope'!G12))="",0,IF(DATE(2027,4,1)=DATE(2026,10,1),'Gainsay drivers · Gainsay fixed'!B21-'Gainsay drivers · Gainsay fixed'!B22,IF('Gainsay economics · Gainsay ope'!G12="","",'Gainsay economics · Gainsay ope'!G12)))+'Gainsay economics · Gainsay ope'!H11 -> 324.27521 | I12: =IF(IF(DATE(2027,5,1)=DATE(2026,10,1),'Gainsay drivers · Gainsay fixed'!B21-'Gainsay drivers · Gainsay fixed'!B22,IF('Gainsay economics · Gainsay ope'!H12="","",'Gainsay economics · Gainsay ope'!H12))="",0,IF(DATE(2027,5,1)=DATE(2026,10,1),'Gainsay drivers · Gainsay fixed'!B21-'Gainsay drivers · Gainsay fixed'!B22,IF('Gainsay economics · Gainsay ope'!H12="","",'Gainsay economics · Gainsay ope'!H12)))+'Gainsay economics · Gainsay ope'!I11 -> 96.99964 | J12: =IF(IF(DATE(2027,6,1)=DATE(2026,10,1),'Gainsay drivers · Gainsay fixed'!B21-'Gainsay drivers · Gainsay fixed'!B22,IF('Gainsay economics · Gainsay ope'!I12="","",'Gainsay economics · Gainsay ope'!I12))="",0,IF(DATE(2027,6,1)=DATE(2026,10,1),'Gainsay drivers · Gainsay fixed'!B21-'Gainsay drivers · Gainsay fixed'!B22,IF('Gainsay economics · Gainsay ope'!I12="","",'Gainsay economics · Gainsay ope'!I12)))+'Gainsay economics · Gainsay ope'!J11 -> -29.886032 | K12: =IF(IF(DATE(2027,7,1)=DATE(2026,10,1),'Gainsay drivers · Gainsay fixed'!B21-'Gainsay drivers · Gainsay fixed'!B22,IF('Gainsay economics · Gainsay ope'!J12="","",'Gainsay economics · Gainsay ope'!J12))="",0,IF(DATE(2027,7,1)=DATE(2026,10,1),'Gainsay drivers · Gainsay fixed'!B21-'Gainsay drivers · Gainsay fixed'!B22,IF('Gainsay economics · Gainsay ope'!J12="","",'Gainsay economics · Gainsay ope'!J12)))+'Gainsay economics · Gainsay ope'!K11 -> -53.199018 | L12: =IF(IF(DATE(2027,8,1)=DATE(2026,10,1),'Gainsay drivers · Gainsay fixed'!B21-'Gainsay drivers · Gainsay fixed'!B22,IF('Gainsay economics · Gainsay ope'!K12="","",'Gainsay economics · Gainsay ope'!K12))="",0,IF(DATE(2027,8,1)=DATE(2026,10,1),'Gainsay drivers · Gainsay fixed'!B21-'Gainsay drivers · Gainsay fixed'!B22,IF('Gainsay economics · Gainsay ope'!K12="","",'Gainsay economics · Gainsay ope'!K12)))+'Gainsay economics · Gainsay ope'!L11 -> 30.457708 | M12: =IF(IF(DATE(2027,9,1)=DATE(2026,10,1),'Gainsay drivers · Gainsay fixed'!B21-'Gainsay drivers · Gainsay fixed'!B22,IF('Gainsay economics · Gainsay ope'!L12="","",'Gainsay economics · Gainsay ope'!L12))="",0,IF(DATE(2027,9,1)=DATE(2026,10,1),'Gainsay drivers · Gainsay fixed'!B21-'Gainsay drivers · Gainsay fixed'!B22,IF('Gainsay economics · Gainsay ope'!L12="","",'Gainsay economics · Gainsay ope'!L12)))+'Gainsay economics · Gainsay ope'!M11 -> 224.70447 | N12: =IF(IF(DATE(2027,10,1)=DATE(2026,10,1),'Gainsay drivers · Gainsay fixed'!B21-'Gainsay drivers · Gainsay fixed'!B22,IF('Gainsay economics · Gainsay ope'!M12="","",'Gainsay economics · Gainsay ope'!M12))="",0,IF(DATE(2027,10,1)=DATE(2026,10,1),'Gainsay drivers · Gainsay fixed'!B21-'Gainsay drivers · Gainsay fixed'!B22,IF('Gainsay economics · Gainsay ope'!M12="","",'Gainsay economics · Gainsay ope'!M12)))+'Gainsay economics · Gainsay ope'!N11 -> 533.39445 | O12: =IF(IF(DATE(2027,11,1)=DATE(2026,10,1),'Gainsay drivers · Gainsay fixed'!B21-'Gainsay drivers · Gainsay fixed'!B22,IF('Gainsay economics · Gainsay ope'!N12="","",'Gainsay economics · Gainsay ope'!N12))="",0,IF(DATE(2027,11,1)=DATE(2026,10,1),'Gainsay drivers · Gainsay fixed'!B21-'Gainsay drivers · Gainsay fixed'!B22,IF('Gainsay economics · Gainsay ope'!N12="","",'Gainsay economics · Gainsay ope'!N12)))+'Gainsay economics · Gainsay ope'!O11 -> 960.62379 | P12: =IF(IF(DATE(2027,12,1)=DATE(2026,10,1),'Gainsay drivers · Gainsay fixed'!B21-'Gainsay drivers · Gainsay fixed'!B22,IF('Gainsay economics · Gainsay ope'!O12="","",'Gainsay economics · Gainsay ope'!O12))="",0,IF(DATE(2027,12,1)=DATE(2026,10,1),'Gainsay drivers · Gainsay fixed'!B21-'Gainsay drivers · Gainsay fixed'!B22,IF('Gainsay economics · Gainsay ope'!O12="","",'Gainsay economics · Gainsay ope'!O12)))+'Gainsay economics · Gainsay ope'!P11 -> 1110.7422
